Erro ao salvar RDO: (psycopg2.errors.NotNullViolation) null value in column "admin_id" of relation "rdo_servico_subatividade" violates not-null constraint DETAIL: Failing row contains (186, 81, 121, Subatividade 0, , 100, 0, 0, null, null, t, null, 2025-09-04 20:42:58.078834, 2025-09-04 20:42:58.078838). [SQL: INSERT INTO rdo_servico_subatividade (rdo_id, servico_id, nome_subatividade, descricao_subatividade, percentual_conclusao, percentual_anterior, incremento_dia, observacoes_tecnicas, ordem_execucao, ativo, admin_id, created_at, updated_at) SELECT p0:: ... 1471 characters truncated ... er) ORDER BY sen_counter RETURNING rdo_servico_subatividade.id, rdo_servico_subatividade.id AS id__1] [parameters: {'servico_id__0': 121, 'created_at__0': datetime.datetime(2025, 9, 4, 20, 42, 58, 78834), 'observacoes_tecnicas__0': None, 'percentual_anterior__0': 0.0, 'ordem_execucao__0': None, 'updated_at__0': datetime.datetime(2025, 9, 4, 20, 42, 58, 78838), 'nome_subatividade__0': 'Subatividade 0', 'admin_id__0': None, 'percentual_conclusao__0': 100.0, 'descricao_subatividade__0': '', 'ativo__0': True, 'incremento_dia__0': 0.0, 'rdo_id__0': 81, 'servico_id__1': 121, 'created_at__1': datetime.datetime(2025, 9, 4, 20, 42, 58, 78840), 'observacoes_tecnicas__1': None, 'percentual_anterior__1': 0.0, 'ordem_execucao__1': None, 'updated_at__1': datetime.datetime(2025, 9, 4, 20, 42, 58, 78840), 'nome_subatividade__1': 'Subatividade 1', 'admin_id__1': None, 'percentual_conclusao__1': 100.0, 'descricao_subatividade__1': '', 'ativo__1': True, 'incremento_dia__1': 0.0, 'rdo_id__1': 81, 'servico_id__2': 121, 'created_at__2': datetime.datetime(2025, 9, 4, 20, 42, 58, 78841), 'observacoes_tecnicas__2': None, 'percentual_anterior__2': 0.0, 'ordem_execucao__2': None, 'updated_at__2': datetime.datetime(2025, 9, 4, 20, 42, 58, 78842), 'nome_subatividade__2': 'Subatividade 2', 'admin_id__2': None, 'percentual_conclusao__2': 0.0, 'descricao_subatividade__2': '', 'ativo__2': True, 'incremento_dia__2': 0.0, 'rdo_id__2': 81, 'servico_id__3': 121, 'created_at__3': datetime.datetime(2025, 9, 4, 20, 42, 58, 78843), 'observacoes_tecnicas__3': None, 'percentual_anterior__3': 0.0, 'ordem_execucao__3': None, 'updated_at__3': datetime.datetime(2025, 9, 4, 20, 42, 58, 78843), 'nome_subatividade__3': 'Subatividade 3', 'admin_id__3': None, 'percentual_conclusao__3': 0.0, 'descricao_subatividade__3': '', 'ativo__3': True, 'incremento_dia__3': 0.0, 'rdo_id__3': 81}] (Background on this error at: https://sqlalche.me/e/20/gkpj)