ERRO DETALHADO: (raised as a result of Query-invoked autoflush; consider using a session.no_autoflush block if this flush is occurring prematurely) (psycopg2.errors.NotNullViolation) null value in column "admin_id" of relation "rdo_servico_subatividade" violates not-null constraint DETAIL: Failing row contains (1, 1, 34, 1. Detalhamento do projeto, null, 100, 0, 0, , null, t, null, 2025-09-04 17:44:28.746855, 2025-09-04 17:44:28.746858). [SQL: INSERT INTO rdo_servico_subatividade (rdo_id, servico_id, nome_subatividade, descricao_subatividade, percentual_conclusao, percentual_anterior, incremento_dia, observacoes_tecnicas, ordem_execucao, ativo, admin_id, created_at, updated_at) VALUES (%(rdo_id)s, %(servico_id)s, %(nome_subatividade)s, %(descricao_subatividade)s, %(percentual_conclusao)s, %(percentual_anterior)s, %(incremento_dia)s, %(observacoes_tecnicas)s, %(ordem_execucao)s, %(ativo)s, %(admin_id)s, %(created_at)s, %(updated_at)s) RETURNING rdo_servico_subatividade.id] [parameters: {'rdo_id': 1, 'servico_id': 34, 'nome_subatividade': '1. Detalhamento do projeto', 'descricao_subatividade': None, 'percentual_conclusao': 100.0, 'percentual_anterior': 0.0, 'incremento_dia': 0.0, 'observacoes_tecnicas': '', 'ordem_execucao': None, 'ativo': True, 'admin_id': None, 'created_at': datetime.datetime(2025, 9, 4, 17, 44, 28, 746855), 'updated_at': datetime.datetime(2025, 9, 4, 17, 44, 28, 746858)}] (Background on this error at: https://sqlalche.me/e/20/gkpj) | USER: contato@estruturasdovale.com.br | ADMIN_ID: None | TRACE: Traceback (most recent call last): File "/usr/local/lib/python3.11/site-packages/sqlalchemy/engine/base.py", line 1967, in _exec_single_context self.dialect.do_execute( File "/usr/local/lib/python3.11/site-packages/sqlalchemy/engine/default.py", line 951, in do_execute cursor.execute(statement, parameters) psycopg2.errors.NotNullViolation: null value in column "admin_id" of relation "rdo_servico_subatividade" violates not-null constraint DETAIL: Failing row contains (1, 1, 34, 1. De...