Erro ao carregar detalhes da obra: (psycopg2.errors.UndefinedColumn) column custo_veiculo.data_vencimento does not exist LINE 1: ..._nota_fiscal AS custo_veiculo_numero_nota_fiscal, custo_veic... ^ [SQL: SELECT custo_veiculo.id AS custo_veiculo_id, custo_veiculo.veiculo_id AS custo_veiculo_veiculo_id, custo_veiculo.data_custo AS custo_veiculo_data_custo, custo_veiculo.tipo_custo AS custo_veiculo_tipo_custo, custo_veiculo.valor AS custo_veiculo_valor, custo_veiculo.descricao AS custo_veiculo_descricao, custo_veiculo.fornecedor AS custo_veiculo_fornecedor, custo_veiculo.numero_nota_fiscal AS custo_veiculo_numero_nota_fiscal, custo_veiculo.data_vencimento AS custo_veiculo_data_vencimento, custo_veiculo.status_pagamento AS custo_veiculo_status_pagamento, custo_veiculo.forma_pagamento AS custo_veiculo_forma_pagamento, custo_veiculo.km_veiculo AS custo_veiculo_km_veiculo, custo_veiculo.observacoes AS custo_veiculo_observacoes, custo_veiculo.admin_id AS custo_veiculo_admin_id, custo_veiculo.created_at AS custo_veiculo_created_at, custo_veiculo.updated_at AS custo_veiculo_updated_at FROM custo_veiculo WHERE custo_veiculo.data_custo >= %(data_custo_1)s AND custo_veiculo.data_custo <= %(data_custo_2)s] [parameters: {'data_custo_1': datetime.date(2025, 7, 1), 'data_custo_2': datetime.date(2025, 8, 31)}] (Background on this error at: https://sqlalche.me/e/20/f405) Traceback: Traceback (most recent call last): File "/usr/local/lib/python3.11/site-packages/sqlalchemy/engine/base.py", line 1967, in _exec_single_context self.dialect.do_execute( File "/usr/local/lib/python3.11/site-packages/sqlalchemy/engine/default.py", line 951, in do_execute cursor.execute(statement, parameters) psycopg2.errors.UndefinedColumn: column custo_veiculo.data_vencimento does not exist LINE 1: ..._nota_fiscal AS custo_veiculo_numero_nota_fiscal, custo_veic... ^ The above exception was the direct cause of the following exception: Traceback (most recent call last): File "/app/views.py", line 2463, in detalhes_obra custos_transporte = custos_query.all() ^^^^^^^^^^^^^^^^^^ File "/usr/local/lib/python3.11/site-packages/sqlalchemy/orm/query.py", line 2704, in all return self._iter().all() # type: ignore ^^^^^^^^^^^^ File "/usr/local/lib/python3.11/site-packages/sqlalchemy/orm/query.py", line 2857, in _iter result: Union[ScalarResult[_T], Result[_T]] = self.session.execute( ^^^^^^^^^^^^^^^^^^^^^ File "/usr/local/lib/python3.11/site-packages/sqlalchemy/orm/session.py", line 2365, in execute return self._execute_internal( ^^^^^^^^^^^^^^^^^^^^^^^ File "/usr/local/lib/python3.11/site-packages/sqlalchemy/orm/session.py", line 2251, in _execute_internal result: Result[Any] = compile_state_cls.orm_execute_statement( ^^^^^^^^^^^^^^^^^^^^^^^^^^^^^^^^^^^^^^^^ File "/usr/local/lib/python3.11/site-packages/sqlalchemy/orm/context.py", line 306, in orm_execute_statement result = conn.execute( ^^^^^^^^^^^^^ File "/usr/local/lib/python3.11/site-packages/sqlalchemy/engine/base.py", line 1419, in execute return meth( ^^^^^ File "/usr/local/lib/python3.11/site-packages/sqlalchemy/sql/elements.py", line 526, in _execute_on_connection return connection._execute_clauseelement( ^^^^^^^^^^^^^^^^^^^^^^^^^^^^^^^^^^ File "/usr/local/lib/python3.11/site-packages/sqlalchemy/engine/base.py", line 1641, in _execute_clauseelement ret = self._execute_context( ^^^^^^^^^^^^^^^^^^^^^^ File "/usr/local/lib/python3.11/site-packages/sqlalchemy/engine/base.py", line 1846, in _execute_context return self._exec_single_context( ^^^^^^^^^^^^^^^^^^^^^^^^^^ File "/usr/local/lib/python3.11/site-packages/sqlalchemy/engine/base.py", line 1986, in _exec_single_context self._handle_dbapi_exception( File "/usr/local/lib/python3.11/site-packages/sqlalchemy/engine/base.py", line 2355, in _handle_dbapi_exception raise sqlalchemy_exception.with_traceback(exc_info[2]) from e File "/usr/local/lib/python3.11/site-packages/sqlalchemy/engine/base.py", line 1967, in _exec_single_context self.dialect.do_execute( File "/usr/local/lib/python3.11/site-packages/sqlalchemy/engine/default.py", line 951, in do_execute cursor.execute(statement, parameters) sqlalchemy.exc.ProgrammingError: (psycopg2.errors.UndefinedColumn) column custo_veiculo.data_vencimento does not exist LINE 1: ..._nota_fiscal AS custo_veiculo_numero_nota_fiscal, custo_veic... ^ [SQL: SELECT custo_veiculo.id AS custo_veiculo_id, custo_veiculo.veiculo_id AS custo_veiculo_veiculo_id, custo_veiculo.data_custo AS custo_veiculo_data_custo, custo_veiculo.tipo_custo AS custo_veiculo_tipo_custo, custo_veiculo.valor AS custo_veiculo_valor, custo_veiculo.descricao AS custo_veiculo_descricao, custo_veiculo.fornecedor AS custo_veiculo_fornecedor, custo_veiculo.numero_nota_fiscal AS custo_veiculo_numero_nota_fiscal, custo_veiculo.data_vencimento AS custo_veiculo_data_vencimento, custo_veiculo.status_pagamento AS custo_veiculo_status_pagamento, custo_veiculo.forma_pagamento AS custo_veiculo_forma_pagamento, custo_veiculo.km_veiculo AS custo_veiculo_km_veiculo, custo_veiculo.observacoes AS custo_veiculo_observacoes, custo_veiculo.admin_id AS custo_veiculo_admin_id, custo_veiculo.created_at AS custo_veiculo_created_at, custo_veiculo.updated_at AS custo_veiculo_updated_at FROM custo_veiculo WHERE custo_veiculo.data_custo >= %(data_custo_1)s AND custo_veiculo.data_custo <= %(data_custo_2)s] [parameters: {'data_custo_1': datetime.date(2025, 7, 1), 'data_custo_2': datetime.date(2025, 8, 31)}] (Background on this error at: https://sqlalche.me/e/20/f405)