ERRO: (psycopg2.errors.UndefinedColumn) column custo_obra.admin_id does not exist
LINE 3: WHERE custo_obra.admin_id = 2
              ^

[SQL: SELECT sum(custo_obra.valor) AS sum_1 
FROM custo_obra 
WHERE custo_obra.admin_id = %(admin_id_1)s]
[parameters: {&#39;admin_id_1&#39;: 2}]
(Background on this error at: https://sqlalche.me/e/20/f405)

TRACE:
Traceback (most recent call last):
  File &#34;/usr/local/lib/python3.11/site-packages/sqlalchemy/engine/base.py&#34;, line 1967, in _exec_single_context
    self.dialect.do_execute(
  File &#34;/usr/local/lib/python3.11/site-packages/sqlalchemy/engine/default.py&#34;, line 951, in do_execute
    cursor.execute(statement, parameters)
psycopg2.errors.UndefinedColumn: column custo_obra.admin_id does not exist
LINE 3: WHERE custo_obra.admin_id = 2
              ^


The above exception was the direct cause of the following exception:

Traceback (most recent call last):
  File &#34;/usr/local/lib/python3.11/site-packages/flask/app.py&#34;, line 917, in full_dispatch_request
    rv = self.dispatch_request()
         ^^^^^^^^^^^^^^^^^^^^^^^
  File &#34;/usr/local/lib/python3.11/site-packages/flask/app.py&#34;, line 902, in dispatch_request
    return self.ensure_sync(self.view_functions[rule.endpoint])(**view_args)  # type: ignore[no-any-return]
           ^^^^^^^^^^^^^^^^^^^^^^^^^^^^^^^^^^^^^^^^^^^^^^^^^^^^^^^^^^^^^^^^^
  File &#34;/usr/local/lib/python3.11/site-packages/flask_login/utils.py&#34;, line 290, in decorated_view
    return current_app.ensure_sync(func)(*args, **kwargs)
           ^^^^^^^^^^^^^^^^^^^^^^^^^^^^^^^^^^^^^^^^^^^^^^
  File &#34;/app/custos_views.py&#34;, line 15, in dashboard_custos
    total_custos = db.session.query(func.sum(CustoObra.valor)).filter_by(admin_id=admin_id).scalar() or 0
                   ^^^^^^^^^^^^^^^^^^^^^^^^^^^^^^^^^^^^^^^^^^^^^^^^^^^^^^^^^^^^^^^^^^^^^^^^^^^^^^^^^
  File &#34;/usr/local/lib/python3.11/site-packages/sqlalchemy/orm/query.py&#34;, line 2835, in scalar
    ret = self.one()
          ^^^^^^^^^^
  File &#34;/usr/local/lib/python3.11/site-packages/sqlalchemy/orm/query.py&#34;, line 2808, in one
    return self._iter().one()  # type: ignore
           ^^^^^^^^^^^^
  File &#34;/usr/local/lib/python3.11/site-packages/sqlalchemy/orm/query.py&#34;, line 2857, in _iter
    result: Union[ScalarResult[_T], Result[_T]] = self.session.execute(
                                                  ^^^^^^^^^^^^^^^^^^^^^
  File &#34;/usr/local/lib/python3.11/site-packages/sqlalchemy/orm/session.py&#34;, line 2351, in execute
    return self._execute_internal(
           ^^^^^^^^^^^^^^^^^^^^^^^
  File &#34;/usr/local/lib/python3.11/site-packages/sqlalchemy/orm/session.py&#34;, line 2249, in _execute_internal
    result: Result[Any] = compile_state_cls.orm_execute_statement(
                          ^^^^^^^^^^^^^^^^^^^^^^^^^^^^^^^^^^^^^^^^
  File &#34;/usr/local/lib/python3.11/site-packages/sqlalchemy/orm/context.py&#34;, line 306, in orm_execute_statement
    result = conn.execute(
             ^^^^^^^^^^^^^
  File &#34;/usr/local/lib/python3.11/site-packages/sqlalchemy/engine/base.py&#34;, line 1419, in execute
    return meth(
           ^^^^^
  File &#34;/usr/local/lib/python3.11/site-packages/sqlalchemy/sql/elements.py&#34;, line 526, in _execute_on_connection
    return connection._execute_clauseelement(
           ^^^^^^^^^^^^^^^^^^^^^^^^^^^^^^^^^^
  File &#34;/usr/local/lib/python3.11/site-packages/sqlalchemy/engine/base.py&#34;, line 1641, in _execute_clauseelement
    ret = self._execute_context(
          ^^^^^^^^^^^^^^^^^^^^^^
  File &#34;/usr/local/lib/python3.11/site-packages/sqlalchemy/engine/base.py&#34;, line 1846, in _execute_context
    return self._exec_single_context(
           ^^^^^^^^^^^^^^^^^^^^^^^^^^
  File &#34;/usr/local/lib/python3.11/site-packages/sqlalchemy/engine/base.py&#34;, line 1986, in _exec_single_context
    self._handle_dbapi_exception(
  File &#34;/usr/local/lib/python3.11/site-packages/sqlalchemy/engine/base.py&#34;, line 2355, in _handle_dbapi_exception
    raise sqlalchemy_exception.with_traceback(exc_info[2]) from e
  File &#34;/usr/local/lib/python3.11/site-packages/sqlalchemy/engine/base.py&#34;, line 1967, in _exec_single_context
    self.dialect.do_execute(
  File &#34;/usr/local/lib/python3.11/site-packages/sqlalchemy/engine/default.py&#34;, line 951, in do_execute
    cursor.execute(statement, parameters)
sqlalchemy.exc.ProgrammingError: (psycopg2.errors.UndefinedColumn) column custo_obra.admin_id does not exist
LINE 3: WHERE custo_obra.admin_id = 2
              ^

[SQL: SELECT sum(custo_obra.valor) AS sum_1 
FROM custo_obra 
WHERE custo_obra.admin_id = %(admin_id_1)s]
[parameters: {&#39;admin_id_1&#39;: 2}]
(Background on this error at: https://sqlalche.me/e/20/f405)
