Erro ao salvar obra: This Session's transaction has been rolled back due to a previous exception during flush. To begin a new transaction with this Session, first issue Session.rollback(). Original exception was: (raised as a result of Query-invoked autoflush; consider using a session.no_autoflush block if this flush is occurring prematurely) (psycopg2.errors.UniqueViolation) duplicate key value violates unique constraint "_servico_obra_real_uc" DETAIL: Key (obra_id, servico_id)=(45, 118) already exists. [SQL: INSERT INTO servico_obra_real (obra_id, servico_id, quantidade_planejada, quantidade_executada, percentual_concluido, data_inicio_planejada, data_fim_planejada, data_inicio_real, data_fim_real, valor_unitario, valor_total_planejado, valor_total_executado, status, prioridade, responsavel_id, observacoes, notas_tecnicas, aprovado, data_aprovacao, aprovado_por_id, admin_id, ativo, created_at, updated_at) VALUES (%(obra_id)s, %(servico_id)s, %(quantidade_planejada)s, %(quantidade_executada)s, %(percentual_concluido)s, %(data_inicio_planejada)s, %(data_fim_planejada)s, %(data_inicio_real)s, %(data_fim_real)s, %(valor_unitario)s, %(valor_total_planejado)s, %(valor_total_executado)s, %(status)s, %(prioridade)s, %(responsavel_id)s, %(observacoes)s, %(notas_tecnicas)s, %(aprovado)s, %(data_aprovacao)s, %(aprovado_por_id)s, %(admin_id)s, %(ativo)s, %(created_at)s, %(updated_at)s) RETURNING servico_obra_real.id] [parameters: {'obra_id': 45, 'servico_id': 118, 'quantidade_planejada': 1.0, 'quantidade_executada': 0.0, 'percentual_concluido': 0.0, 'data_inicio_planejada': datetime.date(2025, 9, 5), 'data_fim_planejada': None, 'data_inicio_real': None, 'data_fim_real': None, 'valor_unitario': 85.0, 'valor_total_planejado': 85.0, 'valor_total_executado': 0.0, 'status': 'Não Iniciado', 'prioridade': 3, 'responsavel_id': None, 'observacoes': 'Serviço adicionado via edição em 05/09/2025', 'notas_tecnicas': None, 'aprovado': False, 'data_aprovacao': None, 'aprovado_por_id': None, 'admin_id': 50, 'ativo': True, 'created_at': datetime.datetime(2025, 9, 5, 12, 39, 22, 439701), 'updated_at': datetime.datetime(2025, 9, 5, 12, 39, 22, 439704)}] (Background on this error at: https://sqlalche.me/e/20/gkpj) (Background on this error at: https://sqlalche.me/e/20/7s2a)