ERRO: Could not build url for endpoint &#39;main_dashboard&#39;. Did you mean &#39;main.dashboard&#39; instead?

TRACE:
Traceback (most recent call last):
  File &#34;/usr/local/lib/python3.11/site-packages/sqlalchemy/sql/base.py&#34;, line 2215, in _entity_namespace_key
    return getattr(ns, key)  # type: ignore
           ^^^^^^^^^^^^^^^^
AttributeError: type object &#39;FleetVehicle&#39; has no attribute &#39;active&#39;

The above exception was the direct cause of the following exception:

Traceback (most recent call last):
  File &#34;/app/fleet_views.py&#34;, line 67, in dashboard
    active_vehicles = FleetVehicle.query.filter_by(admin_id=admin_id, active=True).count()
                      ^^^^^^^^^^^^^^^^^^^^^^^^^^^^^^^^^^^^^^^^^^^^^^^^^^^^^^^^^^^^
  File &#34;/usr/local/lib/python3.11/site-packages/sqlalchemy/orm/query.py&#34;, line 1991, in filter_by
    clauses = [
              ^
  File &#34;/usr/local/lib/python3.11/site-packages/sqlalchemy/orm/query.py&#34;, line 1992, in &lt;listcomp&gt;
    _entity_namespace_key(from_entity, key) == value
    ^^^^^^^^^^^^^^^^^^^^^^^^^^^^^^^^^^^^^^^
  File &#34;/usr/local/lib/python3.11/site-packages/sqlalchemy/sql/base.py&#34;, line 2217, in _entity_namespace_key
    raise exc.InvalidRequestError(
sqlalchemy.exc.InvalidRequestError: Entity namespace for &#34;fleet_vehicle&#34; has no property &#34;active&#34;

During handling of the above exception, another exception occurred:

Traceback (most recent call last):
  File &#34;/usr/local/lib/python3.11/site-packages/flask/app.py&#34;, line 917, in full_dispatch_request
    rv = self.dispatch_request()
         ^^^^^^^^^^^^^^^^^^^^^^^
  File &#34;/usr/local/lib/python3.11/site-packages/flask/app.py&#34;, line 902, in dispatch_request
    return self.ensure_sync(self.view_functions[rule.endpoint])(**view_args)  # type: ignore[no-any-return]
           ^^^^^^^^^^^^^^^^^^^^^^^^^^^^^^^^^^^^^^^^^^^^^^^^^^^^^^^^^^^^^^^^^
  File &#34;/usr/local/lib/python3.11/site-packages/flask_login/utils.py&#34;, line 290, in decorated_view
    return current_app.ensure_sync(func)(*args, **kwargs)
           ^^^^^^^^^^^^^^^^^^^^^^^^^^^^^^^^^^^^^^^^^^^^^^
  File &#34;/app/fleet_views.py&#34;, line 116, in dashboard
    return redirect(url_for(&#39;main_dashboard&#39;))
                    ^^^^^^^^^^^^^^^^^^^^^^^^^
  File &#34;/usr/local/lib/python3.11/site-packages/flask/helpers.py&#34;, line 239, in url_for
    return current_app.url_for(
           ^^^^^^^^^^^^^^^^^^^^
  File &#34;/usr/local/lib/python3.11/site-packages/flask/app.py&#34;, line 1121, in url_for
    return self.handle_url_build_error(error, endpoint, values)
           ^^^^^^^^^^^^^^^^^^^^^^^^^^^^^^^^^^^^^^^^^^^^^^^^^^^^
  File &#34;/usr/local/lib/python3.11/site-packages/flask/app.py&#34;, line 1110, in url_for
    rv = url_adapter.build(  # type: ignore[union-attr]
         ^^^^^^^^^^^^^^^^^^^^^^^^^^^^^^^^^^^^^^^^^^^^^^
  File &#34;/usr/local/lib/python3.11/site-packages/werkzeug/routing/map.py&#34;, line 924, in build
    raise BuildError(endpoint, values, method, self)
werkzeug.routing.exceptions.BuildError: Could not build url for endpoint &#39;main_dashboard&#39;. Did you mean &#39;main.dashboard&#39; instead?
