ERRO: Could not build url for endpoint &#39;main.rdo_lista&#39;. Did you mean &#39;main.rdo_lista_unificada&#39; instead?

TRACE:
Traceback (most recent call last):
  File &#34;/home/runner/workspace/views.py&#34;, line 1776, in excluir_rdo
    admin_id = get_admin_id()
               ^^^^^^^^^^^^
NameError: name &#39;get_admin_id&#39; is not defined

During handling of the above exception, another exception occurred:

Traceback (most recent call last):
  File &#34;/home/runner/workspace/.pythonlibs/lib/python3.11/site-packages/flask/app.py&#34;, line 917, in full_dispatch_request
    rv = self.dispatch_request()
         ^^^^^^^^^^^^^^^^^^^^^^^
  File &#34;/home/runner/workspace/.pythonlibs/lib/python3.11/site-packages/flask/app.py&#34;, line 902, in dispatch_request
    return self.ensure_sync(self.view_functions[rule.endpoint])(**view_args)  # type: ignore[no-any-return]
           ^^^^^^^^^^^^^^^^^^^^^^^^^^^^^^^^^^^^^^^^^^^^^^^^^^^^^^^^^^^^^^^^^
  File &#34;/home/runner/workspace/auth.py&#34;, line 44, in decorated_function
    return f(*args, **kwargs)
           ^^^^^^^^^^^^^^^^^^
  File &#34;/home/runner/workspace/views.py&#34;, line 1804, in excluir_rdo
    return redirect(url_for(&#39;main.rdo_lista&#39;))
                    ^^^^^^^^^^^^^^^^^^^^^^^^^
  File &#34;/home/runner/workspace/.pythonlibs/lib/python3.11/site-packages/flask/helpers.py&#34;, line 232, in url_for
    return current_app.url_for(
           ^^^^^^^^^^^^^^^^^^^^
  File &#34;/home/runner/workspace/.pythonlibs/lib/python3.11/site-packages/flask/app.py&#34;, line 1121, in url_for
    return self.handle_url_build_error(error, endpoint, values)
           ^^^^^^^^^^^^^^^^^^^^^^^^^^^^^^^^^^^^^^^^^^^^^^^^^^^^
  File &#34;/home/runner/workspace/.pythonlibs/lib/python3.11/site-packages/flask/app.py&#34;, line 1110, in url_for
    rv = url_adapter.build(  # type: ignore[union-attr]
         ^^^^^^^^^^^^^^^^^^^^^^^^^^^^^^^^^^^^^^^^^^^^^^
  File &#34;/home/runner/workspace/.pythonlibs/lib/python3.11/site-packages/werkzeug/routing/map.py&#34;, line 924, in build
    raise BuildError(endpoint, values, method, self)
werkzeug.routing.exceptions.BuildError: Could not build url for endpoint &#39;main.rdo_lista&#39;. Did you mean &#39;main.rdo_lista_unificada&#39; instead?
