ERRO: Could not build url for endpoint &#39;main.novo_ponto&#39;. Did you mean &#39;main.novo_rdo&#39; instead?

TRACE:
Traceback (most recent call last):
  File &#34;/usr/local/lib/python3.11/site-packages/flask/app.py&#34;, line 917, in full_dispatch_request
    rv = self.dispatch_request()
         ^^^^^^^^^^^^^^^^^^^^^^^
  File &#34;/usr/local/lib/python3.11/site-packages/flask/app.py&#34;, line 902, in dispatch_request
    return self.ensure_sync(self.view_functions[rule.endpoint])(**view_args)  # type: ignore[no-any-return]
           ^^^^^^^^^^^^^^^^^^^^^^^^^^^^^^^^^^^^^^^^^^^^^^^^^^^^^^^^^^^^^^^^^
  File &#34;/app/views.py&#34;, line 1083, in funcionario_perfil
    return render_template(&#39;funcionario_perfil.html&#39;,
          ^^^^^^^^^^^^^^^^^^^^^^^^^^^^^^^^^^^^^^^^^^
  File &#34;/usr/local/lib/python3.11/site-packages/flask/templating.py&#34;, line 150, in render_template
    return _render(app, template, context)
           ^^^^^^^^^^^^^^^^^^^^^^^^^^^^^^^
  File &#34;/usr/local/lib/python3.11/site-packages/flask/templating.py&#34;, line 131, in _render
    rv = template.render(context)
         ^^^^^^^^^^^^^^^^^^^^^^^^
  File &#34;/usr/local/lib/python3.11/site-packages/jinja2/environment.py&#34;, line 1295, in render
    self.environment.handle_exception()
  File &#34;/usr/local/lib/python3.11/site-packages/jinja2/environment.py&#34;, line 942, in handle_exception
    raise rewrite_traceback_stack(source=source)
  File &#34;/app/templates/funcionario_perfil.html&#34;, line 1, in top-level template code
    {% extends &#34;base_completo.html&#34; %}
    ^^^^^^^^^^^^^^^^^^^^^^^^^
  File &#34;/app/templates/base_completo.html&#34;, line 852, in top-level template code
    {% block content %}{% endblock %}
    ^^^^^^^^^^^^^^^^^^^^^^^^^
  File &#34;/app/templates/funcionario_perfil.html&#34;, line 778, in block &#39;content&#39;
    &lt;form method=&#34;POST&#34; id=&#34;pontoForm&#34; action=&#34;{{ url_for(&#39;main.novo_ponto&#39;) }}&#34; onsubmit=&#34;return salvarPonto(event)&#34;&gt;
    ^^^^^^^^^^^^^^^^^^^^^^^^^
  File &#34;/usr/local/lib/python3.11/site-packages/flask/app.py&#34;, line 1121, in url_for
    return self.handle_url_build_error(error, endpoint, values)
           ^^^^^^^^^^^^^^^^^^^^^^^^^^^^^^^^^^^^^^^^^^^^^^^^^^^^
  File &#34;/usr/local/lib/python3.11/site-packages/flask/app.py&#34;, line 1110, in url_for
    rv = url_adapter.build(  # type: ignore[union-attr]
         ^^^^^^^^^^^^^^^^^^^^^^^^^^^^^^^^^^^^^^^^^^^^^^
  File &#34;/usr/local/lib/python3.11/site-packages/werkzeug/routing/map.py&#34;, line 924, in build
    raise BuildError(endpoint, values, method, self)
werkzeug.routing.exceptions.BuildError: Could not build url for endpoint &#39;main.novo_ponto&#39;. Did you mean &#39;main.novo_rdo&#39; instead?
